Workbook

Sheet Dashboard
B1: ACQUISITION CALL TRACKER
B2: Home Services Roll-Up | Auto-updates from Companies, Call Log and SMS Nurture
B4: ACTIVITY | E4: PIPELINE BY STAGE | F4: # COS | G4: EBITDA IN STAGE | I4: TEAM ACTIVITY
B5: Target companies in database | C5: =COUNTA(Companies!B2:B1000) -> 906 | E5: 1. Not Contacted | F5: =COUNTIF(Companies!$M$2:$M$1000,E5) -> 906 | G5: =SUMIF(Companies!$M$2:$M$1000,E5,Companies!$F$2:$F$1000) -> 203069000 | I5: Caller | J5: Total Calls | K5: This Week | L5: DM Convos | M5: Meetings Set
B6: Total calls logged | C6: =COUNTA('Call Log'!A2:A5000) -> 0 | E6: 2. In Call Rotation | F6: =COUNTIF(Companies!$M$2:$M$1000,E6) -> 0 | G6: =SUMIF(Companies!$M$2:$M$1000,E6,Companies!$F$2:$F$1000) -> 0 | I6: =Lists!D2 -> Xander | J6: =COUNTIF('Call Log'!$B$2:$B$5000,I6) -> 0 | K6: =COUNTIFS('Call Log'!$B$2:$B$5000,I6,'Call Log'!$A$2:$A$5000,">="&(TODAY()-WEEKDAY(TODAY(),2)+1)) -> 0 | L6: =COUNTIFS('Call Log'!$B$2:$B$5000,I6,'Call Log'!$D$2:$D$5000,"Owner (Decision Maker)") -> 0 | M6: =COUNTIFS('Call Log'!$B$2:$B$5000,I6,'Call Log'!$E$2:$E$5000,"Meeting Set") -> 0
B7: Calls this week (Mon-Sun) | C7: =COUNTIFS('Call Log'!A2:A5000,">="&(TODAY()-WEEKDAY(TODAY(),2)+1)) -> 0 | E7: 3. Meeting Set | F7: =COUNTIF(Companies!$M$2:$M$1000,E7) -> 0 | G7: =SUMIF(Companies!$M$2:$M$1000,E7,Companies!$F$2:$F$1000) -> 0 | I7: =Lists!D3 -> Bram | J7: =COUNTIF('Call Log'!$B$2:$B$5000,I7) -> 0 | K7: =COUNTIFS('Call Log'!$B$2:$B$5000,I7,'Call Log'!$A$2:$A$5000,">="&(TODAY()-WEEKDAY(TODAY(),2)+1)) -> 0 | L7: =COUNTIFS('Call Log'!$B$2:$B$5000,I7,'Call Log'!$D$2:$D$5000,"Owner (Decision Maker)") -> 0 | M7: =COUNTIFS('Call Log'!$B$2:$B$5000,I7,'Call Log'!$E$2:$E$5000,"Meeting Set") -> 0
B8: Owner (DM) reach rate | C8: =IFERROR(COUNTIF('Call Log'!D2:D5000,"Owner (Decision Maker)")/COUNTA('Call Log'!A2:A5000),0) -> 0 | E8: 4. Meeting Held | F8: =COUNTIF(Companies!$M$2:$M$1000,E8) -> 0 | G8: =SUMIF(Companies!$M$2:$M$1000,E8,Companies!$F$2:$F$1000) -> 0 | I8: =Lists!D4 -> Andrew | J8: =COUNTIF('Call Log'!$B$2:$B$5000,I8) -> 0 | K8: =COUNTIFS('Call Log'!$B$2:$B$5000,I8,'Call Log'!$A$2:$A$5000,">="&(TODAY()-WEEKDAY(TODAY(),2)+1)) -> 0 | L8: =COUNTIFS('Call Log'!$B$2:$B$5000,I8,'Call Log'!$D$2:$D$5000,"Owner (Decision Maker)") -> 0 | M8: =COUNTIFS('Call Log'!$B$2:$B$5000,I8,'Call Log'!$E$2:$E$5000,"Meeting Set") -> 0
B9: Meetings set (in pipeline now) | C9: =COUNTIF(Companies!M2:M1000,"3. Meeting Set") -> 0 | E9: 5. NDA Signed | F9: =COUNTIF(Companies!$M$2:$M$1000,E9) -> 0 | G9: =SUMIF(Companies!$M$2:$M$1000,E9,Companies!$F$2:$F$1000) -> 0 | I9: =Lists!D5 -> Davis | J9: =COUNTIF('Call Log'!$B$2:$B$5000,I9) -> 0 | K9: =COUNTIFS('Call Log'!$B$2:$B$5000,I9,'Call Log'!$A$2:$A$5000,">="&(TODAY()-WEEKDAY(TODAY(),2)+1)) -> 0 | L9: =COUNTIFS('Call Log'!$B$2:$B$5000,I9,'Call Log'!$D$2:$D$5000,"Owner (Decision Maker)") -> 0 | M9: =COUNTIFS('Call Log'!$B$2:$B$5000,I9,'Call Log'!$E$2:$E$5000,"Meeting Set") -> 0
B10: Upcoming meetings on calendar | C10: =COUNTIF(Companies!U2:U1000,">="&TODAY()) -> 0 | E10: 6. Financials Received | F10: =COUNTIF(Companies!$M$2:$M$1000,E10) -> 0 | G10: =SUMIF(Companies!$M$2:$M$1000,E10,Companies!$F$2:$F$1000) -> 0 | I10: =Lists!D6 -> TJ | J10: =COUNTIF('Call Log'!$B$2:$B$5000,I10) -> 0 | K10: =COUNTIFS('Call Log'!$B$2:$B$5000,I10,'Call Log'!$A$2:$A$5000,">="&(TODAY()-WEEKDAY(TODAY(),2)+1)) -> 0 | L10: =COUNTIFS('Call Log'!$B$2:$B$5000,I10,'Call Log'!$D$2:$D$5000,"Owner (Decision Maker)") -> 0 | M10: =COUNTIFS('Call Log'!$B$2:$B$5000,I10,'Call Log'!$E$2:$E$5000,"Meeting Set") -> 0
B11: Follow-ups OVERDUE | C11: =COUNTIF(Companies!T2:T1000,"<"&TODAY()) -> 0 | E11: 7. LOI Submitted | F11: =COUNTIF(Companies!$M$2:$M$1000,E11) -> 0 | G11: =SUMIF(Companies!$M$2:$M$1000,E11,Companies!$F$2:$F$1000) -> 0
B12: Follow-ups due today | C12: =COUNTIF(Companies!T2:T1000,TODAY()) -> 0 | E12: 8. Diligence | F12: =COUNTIF(Companies!$M$2:$M$1000,E12) -> 0 | G12: =SUMIF(Companies!$M$2:$M$1000,E12,Companies!$F$2:$F$1000) -> 0
B13: In rotation, ZERO calls this wk | C13: =COUNTIFS(Companies!M2:M1000,"2. In Call Rotation",Companies!P2:P1000,0) -> 0 | E13: 9. Closed - Acquired | F13: =COUNTIF(Companies!$M$2:$M$1000,E13) -> 0 | G13: =SUMIF(Companies!$M$2:$M$1000,E13,Companies!$F$2:$F$1000) -> 0 | I13: DAILY ROUTINE
B14: On SMS nurture list | C14: =COUNTA('SMS Nurture'!A2:A500) -> 0 | E14: X. SMS Nurture (Said No) | F14: =COUNTIF(Companies!$M$2:$M$1000,E14) -> 0 | G14: =SUMIF(Companies!$M$2:$M$1000,E14,Companies!$F$2:$F$1000) -> 0 | I14: 1. Clear anything RED (overdue follow-ups on Companies).
B15: Texts due to send now | C15: =COUNTIFS('SMS Nurture'!G2:G500,"<="&TODAY(),'SMS Nurture'!H2:H500,"<>OPTED OUT - never text again") -> 0 | I15: 2. Check 'In rotation, ZERO calls this wk' - orange rows on Companies need a dial today.
B16: Hot targets | C16: =COUNTIF(Companies!N2:N1000,"Hot") -> 0 | I16: 3. Send any SMS due (yellow rows on SMS Nurture tab).
E17: BY TRADE | F17: # COS | I17: 4. Log every dial in Call Log the moment it ends - even no-answers.
E18: HVAC | F18: =COUNTIF(Companies!$H$2:$H$1000,E18) -> 469
E19: Plumbing | F19: =COUNTIF(Companies!$H$2:$H$1000,E19) -> 393
E20: Electrical | F20: =COUNTIF(Companies!$H$2:$H$1000,E20) -> 0
E21: HVAC + Plumbing | F21: =COUNTIF(Companies!$H$2:$H$1000,E21) -> 44
E22: Multi-Trade | F22: =COUNTIF(Companies!$H$2:$H$1000,E22) -> 0

Sheet Lists
A1: Stage | B1: Trade | C1: Interest | D1: Caller | E1: Reached | F1: Call Outcome | G1: Lead Source | H1: SMS Status
A2: 1. Not Contacted | B2: HVAC | C2: Hot | D2: Xander | E2: Owner (Decision Maker) | F2: Meeting Set | G2: Google Maps scrape | H2: No reply yet
A3: 2. In Call Rotation | B3: Plumbing | C3: Warm | D3: Bram | E3: Voicemail | F3: Meaningful Conversation | G3: Purchased list | H3: Replied - still no
A4: 3. Meeting Set | B4: Electrical | C4: Lukewarm | D4: Andrew | E4: No Answer | F4: Callback Scheduled | G4: Referral | H4: Replied - INTERESTED
A5: 4. Meeting Held | B5: HVAC + Plumbing | C5: Cold | D5: Davis | E5: Gatekeeper | F5: Left Voicemail | G5: BizBuySell | H5: OPTED OUT - never text again
A6: 5. NDA Signed | B6: Multi-Trade | C6: Said No | D6: TJ | E6: Wrong Number | F6: No Answer | G6: Broker
A7: 6. Financials Received | C7: Unknown | F7: Not Interested - move to SMS List | G7: Trade association
A8: 7. LOI Submitted | F8: Bad Number | G8: Other
A9: 8. Diligence | D9: <- Your team; edit here if the roster changes | F9: Do Not Contact (asked us to stop)
A10: 9. Closed - Acquired
A11: X. SMS Nurture (Said No)

Sheet Companies
A1: ID | B1: Company Name | C1: Owner Name | D1: Owner Cell | E1: Employees | F1: EBITDA / SDE ($) | G1: Est. Revenue ($) | H1: Trade | I1: City | J1: State | K1: Office Phone | L1: Email | M1: Stage | N1: Interest | O1: Last Caller | P1: Calls This Wk | Q1: Total Calls | R1: Last Call | S1: Next Caller | T1: Next Action Date | U1: Meeting Date | V1: Meeting Time & Place | W1: Asking Price ($) | X1: Trucks | Y1: Owner Age / Motivation | Z1: Lead Source | AA1: Notes
A2: C001 | B2: Geary Pacific Supply | C2: Russ Geary | D2: (916) 716-6726 | E2: 250 | F2: 8019000 | G2: 66825000 | H2: HVAC | I2: Kingman | J2: AZ | K2: (928) 718-7177 | L2: russ@gearypacific.com | M2: 1. Not Contacted | N2: Unknown | O2: =IF(B2="","",IFERROR(LOOKUP(2,1/('Call Log'!$C$2:$C$5000=B2),'Call Log'!$B$2:$B$5000),"")) | P2: =IF(B2="","",COUNTIFS('Call Log'!$C$2:$C$5000,B2,'Call Log'!$A$2:$A$5000,">="&(TODAY()-WEEKDAY(TODAY(),2)+1))) -> 0 | Q2: =IF(B2="","",COUNTIF('Call Log'!$C$2:$C$5000,B2)) -> 0 | R2: =IF(B2="","",IFERROR(IF(MAXIFS('Call Log'!$A$2:$A$5000,'Call Log'!$C$2:$C$5000,B2)=0,"",MAXIFS('Call Log'!$A$2:$A$5000,'Call Log'!$C$2:$C$5000,B2)),"")) | AA2: Contact title 'Regional V.P.' - verify decision maker | Owner found via Apollo | EBITDA = 12% revenue proxy
A3: C002 | B3: Any Hour Services - Electric, Plumbing, Heating & Air | C3: Angedet Thomas | D3: (757) 337-4204 | E3: 260 | F3: 5208000 | G3: 43400000 | H3: HVAC + Plumbing | I3: Phoenix | J3: AZ | K3: (602) 609-7184 | M3: 1. Not Contacted | N3: Unknown | O3: =IF(B3="","",IFERROR(LOOKUP(2,1/('Call Log'!$C$2:$C$5000=B3),'Call Log'!$B$2:$B$5000),"")) | P3: =IF(B3="","",COUNTIFS('Call Log'!$C$2:$C$5000,B3,'Call Log'!$A$2:$A$5000,">="&(TODAY()-WEEKDAY(TODAY(),2)+1))) -> 0 | Q3: =IF(B3="","",COUNTIF('Call Log'!$C$2:$C$5000,B3)) -> 0 | R3: =IF(B3="","",IFERROR(IF(MAXIFS('Call Log'!$A$2:$A$5000,'Call Log'!$C$2:$C$5000,B3)=0,"",MAXIFS('Call Log'!$A$2:$A$5000,'Call Log'!$C$2:$C$5000,B3)),"")) | AA3: Owner found via Apollo | EBITDA = 12% revenue proxy
A4: C003 | B4: Area Plumbing | C4: Jason Griffin | D4: (928) 388-5459 | E4: 5 | F4: 5013000 | G4: 41775000 | H4: Plumbing | I4: Yuma | J4: AZ | K4: (928) 344-0868 | L4: jason@areaplumbing.com | M4: 1. Not Contacted | N4: Unknown | O4: =IF(B4="","",IFERROR(LOOKUP(2,1/('Call Log'!$C$2:$C$5000=B4),'Call Log'!$B$2:$B$5000),"")) | P4: =IF(B4="","",COUNTIFS('Call Log'!$C$2:$C$5000,B4,'Call Log'!$A$2:$A$5000,">="&(TODAY()-WEEKDAY(TODAY(),2)+1))) -> 0 | Q4: =IF(B4="","",COUNTIF('Call Log'!$C$2:$C$5000,B4)) -> 0 | R4: =IF(B4="","",IFERROR(IF(MAXIFS('Call Log'!$A$2:$A$5000,'Call Log'!$C$2:$C$5000,B4)=0,"",MAXIFS('Call Log'!$A$2:$A$5000,'Call Log'!$C$2:$C$5000,B4)),"")) | Z4: roc-posting-list | AA4: Contact title 'General Manager' - verify decision maker | ROC 105658 R-37 | EBITDA = 12% revenue proxy | Size est. midpoint - ZoomInfo: 1-10 employees
A5: C004 | B5: TDK Comfort Systems Inc | C5: Troy Douglas Koski | D5: (928) 237-6050 | E5: 5 | F5: 3897000 | G5: 32476000 | H5: HVAC | I5: Chino Valley | J5: AZ | K5: (928) 636-0846 | L5: troy@tdkcomfortsystems.com | M5: 1. Not Contacted | N5: Unknown | O5: =IF(B5="","",IFERROR(LOOKUP(2,1/('Call Log'!$C$2:$C$5000=B5),'Call Log'!$B$2:$B$5000),"")) | P5: =IF(B5="","",COUNTIFS('Call Log'!$C$2:$C$5000,B5,'Call Log'!$A$2:$A$5000,">="&(TODAY()-WEEKDAY(TODAY(),2)+1))) -> 0 | Q5: =IF(B5="","",COUNTIF('Call Log'!$C$2:$C$5000,B5)) -> 0 | R5: =IF(B5="","",IFERROR(IF(MAXIFS('Call Log'!$A$2:$A$5000,'Call Log'!$C$2:$C$5000,B5)=0,"",MAXIFS('Call Log'!$A$2:$A$5000,'Call Log'!$C$2:$C$5000,B5)),"")) | Z5: roc-posting-list | AA5: ROC 154061 CR-39 | EBITDA = 12% revenue proxy
A6: C005 | B6: Hamstra Heating & Cooling | C6: Wade Hamstra | D6: (520) 250-1796 | E6: 35 | F6: 3667000 | G6: 30559000 | H6: HVAC | I6: Tucson | J6: AZ | K6: (520) 629-9833 | L6: whamstra@hamstraac.com | M6: 1. Not Contacted | N6: Unknown | O6: =IF(B6="","",IFERROR(LOOKUP(2,1/('Call Log'!$C$2:$C$5000=B6),'Call Log'!$B$2:$B$5000),"")) | P6: =IF(B6="","",COUNTIFS('Call Log'!$C$2:$C$5000,B6,'Call Log'!$A$2:$A$5000,">="&(TODAY()-WEEKDAY(TODAY(),2)+1))) -> 0 | Q6: =IF(B6="","",COUNTIF('Call Log'!$C$2:$C$5000,B6)) -> 0 | R6: =IF(B6="","",IFERROR(IF(MAXIFS('Call Log'!$A$2:$A$5000,'Call Log'!$C$2:$C$5000,B6)=0,"",MAXIFS('Call Log'!$A$2:$A$5000,'Call Log'!$C$2:$C$5000,B6)),"")) | AA6: Contact title 'Owner, Vice President' - verify decision maker | Owner found via Apollo | ROC 59073 R-39R | EBITDA = 12% revenue proxy
A7: C006 | B7: Wolfgangs Cooling, Heating & Plumbing | C7: Tom Doll | D7: (480) 529-9926 | E7: 25 | F7: 3329000 | G7: 27745000 | H7: HVAC | I7: Tempe | J7: AZ | K7: (928) 228-5968 | M7: 1. Not Contacted | N7: Unknown | O7: =IF(B7="","",IFERROR(LOOKUP(2,1/('Call Log'!$C$2:$C$5000=B7),'Call Log'!$B$2:$B$5000),"")) | P7: =IF(B7="","",COUNTIFS('Call Log'!$C$2:$C$5000,B7,'Call Log'!$A$2:$A$5000,">="&(TODAY()-WEEKDAY(TODAY(),2)+1))) -> 0 | Q7: =IF(B7="","",COUNTIF('Call Log'!$C$2:$C$5000,B7)) -> 0 | R7: =IF(B7="","",IFERROR(IF(MAXIFS('Call Log'!$A$2:$A$5000,'Call Log'!$C$2:$C$5000,B7)=0,"",MAXIFS('Call Log'!$A$2:$A$5000,'Call Log'!$C$2:$C$5000,B7)),"")) | AA7: Contact title 'President' - verify decision maker | Other locations: Prescott Valley | Owner found via Apollo | EBITDA = 12% revenue proxy
A8: C007 | B8: Chandler Air | C8: Ryan Bond | D8: (602) 684-0267 | E8: 30 | F8: 3142000 | G8: 26185000 | H8: HVAC | I8: Chandler | J8: AZ | K8: (480) 372-5008 | M8: 1. Not Contacted | N8: Unknown | O8: =IF(B8="","",IFERROR(LOOKUP(2,1/('Call Log'!$C$2:$C$5000=B8),'Call Log'!$B$2:$B$5000),"")) | P8: =IF(B8="","",COUNTIFS('Call Log'!$C$2:$C$5000,B8,'Call Log'!$A$2:$A$5000,">="&(TODAY()-WEEKDAY(TODAY(),2)+1))) -> 0 | Q8: =IF(B8="","",COUNTIF('Call Log'!$C$2:$C$5000,B8)) -> 0 | R8: =IF(B8="","",IFERROR(IF(MAXIFS('Call Log'!$A$2:$A$5000,'Call Log'!$C$2:$C$5000,B8)=0,"",MAXIFS('Call Log'!$A$2:$A$5000,'Call Log'!$C$2:$C$5000,B8)),"")) | Z8: roc-posting-list | AA8: Contact title 'Owner and Principal' - verify decision maker | ROC 220890 C-39 | EBITDA = 12% revenue proxy | Size est. midpoint - ZoomInfo: 11-50 employees
A9: C008 | B9: Mason Pro Services | C9: Paden James Mason | D9: (480) 797-4839 | E9: 30 | F9: 2970000 | G9: 24747000 | H9: HVAC | I9: Chandler | J9: AZ | K9: (480) 835-9928 | L9: paden@masonproservices.com | M9: 1. Not Contacted | N9: Unknown | O9: =IF(B9="","",IFERROR(LOOKUP(2,1/('Call Log'!$C$2:$C$5000=B9),'Call Log'!$B$2:$B$5000),"")) | P9: =IF(B9="","",COUNTIFS('Call Log'!$C$2:$C$5000,B9,'Call Log'!$A$2:$A$5000,">="&(TODAY()-WEEKDAY(TODAY(),2)+1))) -> 0 | Q9: =IF(B9="","",COUNTIF('Call Log'!$C$2:$C$5000,B9)) -> 0 | R9: =IF(B9="","",IFERROR(IF(MAXIFS('Call Log'!$A$2:$A$5000,'Call Log'!$C$2:$C$5000,B9)=0,"",MAXIFS('Call Log'!$A$2:$A$5000,'Call Log'!$C$2:$C$5000,B9)),"")) | Z9: roc-posting-list | AA9: Contact title 'Service Administrator' - verify decision maker | ROC 331897 CR-37 | EBITDA = 12% revenue proxy
A10: C009 | B10: Superstition Plumbing | C10: Roy Glenn Jorgenson | D10: (801) 678-2030 | E10: 3 | F10: 2854000 | G10: 23785000 | H10: Plumbing | I10: Mesa | J10: AZ | K10: (480) 833-3112 | L10: roy@superstitionplumbing.com | M10: 1. Not Contacted | N10: Unknown | O10: =IF(B10="","",IFERROR(LOOKUP(2,1/('Call Log'!$C$2:$C$5000=B10),'Call Log'!$B$2:$B$5000),"")) | P10: =IF(B10="","",COUNTIFS('Call Log'!$C$2:$C$5000,B10,'Call Log'!$A$2:$A$5000,">="&(TODAY()-WEEKDAY(TODAY(),2)+1))) -> 0 | Q10: =IF(B10="","",COUNTIF('Call Log'!$C$2:$C$5000,B10)) -> 0 | R10: =IF(B10="","",IFERROR(IF(MAXIFS('Call Log'!$A$2:$A$5000,'Call Log'!$C$2:$C$5000,B10)=0,"",MAXIFS('Call Log'!$A$2:$A$5000,'Call Log'!$C$2:$C$5000,B10)),"")) | Z10: roc-apify | AA10: ROC 361375 | EBITDA = 12% revenue proxy
A11: C010 | B11: Plumbing Masters | C11: Brian Joe McQuistion | D11: (602) 377-6931 | E11: 29 | F11: 2798000 | G11: 23317000 | H11: Plumbing | I11: Peoria | J11: AZ | K11: (602) 637-0315 | L11: plumbingmasters9299bm@myplumberaz.com | M11: 1. Not Contacted | N11: Unknown | O11: =IF(B11="","",IFERROR(LOOKUP(2,1/('Call Log'!$C$2:$C$5000=B11),'Call Log'!$B$2:$B$5000),"")) | P11: =IF(B11="","",COUNTIFS('Call Log'!$C$2:$C$5000,B11,'Call Log'!$A$2:$A$5000,">="&(TODAY()-WEEKDAY(TODAY(),2)+1))) -> 0 | Q11: =IF(B11="","",COUNTIF('Call Log'!$C$2:$C$5000,B11)) -> 0 | R11: =IF(B11="","",IFERROR(IF(MAXIFS('Call Log'!$A$2:$A$5000,'Call Log'!$C$2:$C$5000,B11)=0,"",MAXIFS('Call Log'!$A$2:$A$5000,'Call Log'!$C$2:$C$5000,B11)),"")) | Z11: roc-apify | AA11: Other locations: Mesa | ROC 255233 | EBITDA = 12% revenue proxy
A12: C011 | B12: Hendel's Air Conditioning Inc. | C12: Robert Jason Hendel | D12: (631) 804-7361 | E12: 8 | F12: 2743000 | G12: 22861000 | H12: HVAC | I12: Chandler | J12: AZ | K12: (480) 813-1700 | M12: 1. Not Contacted | N12: Unknown | O12: =IF(B12="","",IFERROR(LOOKUP(2,1/('Call Log'!$C$2:$C$5000=B12),'Call Log'!$B$2:$B$5000),"")) | P12: =IF(B12="","",COUNTIFS('Call Log'!$C$2:$C$5000,B12,'Call Log'!$A$2:$A$5000,">="&(TODAY()-WEEKDAY(TODAY(),2)+1))) -> 0 | Q12: =IF(B12="","",COUNTIF('Call Log'!$C$2:$C$5000,B12)) -> 0 | R12: =IF(B12="","",IFERROR(IF(MAXIFS('Call Log'!$A$2:$A$5000,'Call Log'!$C$2:$C$5000,B12)=0,"",MAXIFS('Call Log'!$A$2:$A$5000,'Call Log'!$C$2:$C$5000,B12)),"")) | Z12: roc-posting-list | AA12: Co-owners: Julia Hendel | Contact title 'General Manager' - verify decision maker | ROC 50612 R-39R | EBITDA = 12% revenue proxy
A13: C012 | B13: Rim Country Mechanical Inc | C13: Corey Lunt | D13: (928) 242-1660 | E13: 9 | F13: 2522000 | G13: 21014000 | H13: HVAC | I13: Show Low | J13: AZ | K13: (928) 537-1803 | L13: coreylunt@rimcountrymechanical.com | M13: 1. Not Contacted | N13: Unknown | O13: =IF(B13="","",IFERROR(LOOKUP(2,1/('Call Log'!$C$2:$C$5000=B13),'Call Log'!$B$2:$B$5000),"")) | P13: =IF(B13="","",COUNTIFS('Call Log'!$C$2:$C$5000,B13,'Call Log'!$A$2:$A$5000,">="&(TODAY()-WEEKDAY(TODAY(),2)+1))) -> 0 | Q13: =IF(B13="","",COUNTIF('Call Log'!$C$2:$C$5000,B13)) -> 0 | R13: =IF(B13="","",IFERROR(IF(MAXIFS('Call Log'!$A$2:$A$5000,'Call Log'!$C$2:$C$5000,B13)=0,"",MAXIFS('Call Log'!$A$2:$A$5000,'Call Log'!$C$2:$C$5000,B13)),"")) | Z13: roc-posting-list | AA13: ROC 285833 CR-79 | EBITDA = 12% revenue proxy
A14: C013 | B14: Sav-On Plumbing | C14: Paul Johnson | D14: (619) 823-7851 | E14: 4 | F14: 2508000 | G14: 20904000 | H14: Plumbing | I14: Glendale | J14: AZ | K14: (623) 487-9500 | L14: paul@sav-onplumbing.com | M14: 1. Not Contacted | N14: Unknown | O14: =IF(B14="","",IFERROR(LOOKUP(2,1/('Call Log'!$C$2:$C$5000=B14),'Call Log'!$B$2:$B$5000),"")) | P14: =IF(B14="","",COUNTIFS('Call Log'!$C$2:$C$5000,B14,'Call Log'!$A$2:$A$5000,">="&(TODAY()-WEEKDAY(TODAY(),2)+1))) -> 0 | Q14: =IF(B14="","",COUNTIF('Call Log'!$C$2:$C$5000,B14)) -> 0 | R14: =IF(B14="","",IFERROR(IF(MAXIFS('Call Log'!$A$2:$A$5000,'Call Log'!$C$2:$C$5000,B14)=0,"",MAXIFS('Call Log'!$A$2:$A$5000,'Call Log'!$C$2:$C$5000,B14)),"")) | AA14: Owner found via Apollo | EBITDA = 12% revenue proxy
A15: C014 | B15: ACE Home Services (formerly Yavapai Plumbing & Heating) | C15: Jay Hazlewood | D15: (480) 717-9339 | E15: 110 | F15: 2400000 | G15: 20000000 | H15: HVAC + Plumbing | I15: Prescott | J15: AZ | K15: (928) 683-7898 | M15: 1. Not Contacted | N15: Unknown | O15: =IF(B15="","",IFERROR(LOOKUP(2,1/('Call Log'!$C$2:$C$5000=B15),'Call Log'!$B$2:$B$5000),"")) | P15: =IF(B15="","",COUNTIFS('Call Log'!$C$2:$C$5000,B15,'Call Log'!$A$2:$A$5000,">="&(TODAY()-WEEKDAY(TODAY(),2)+1))) -> 0 | Q15: =IF(B15="","",COUNTIF('Call Log'!$C$2:$C$5000,B15)) -> 0 | R15: =IF(B15="","",IFERROR(IF(MAXIFS('Call Log'!$A$2:$A$5000,'Call Log'!$C$2:$C$5000,B15)=0,"",MAXIFS('Call Log'!$A$2:$A$5000,'Call Log'!$C$2:$C$5000,B15)),"")) | AA15: Contact title 'Owner' - verify decision maker | Owner found via Apollo | EBITDA = 12% revenue proxy
A16: C015 | B16: ACE Home Services (formerly AZ Best Plumbing) | C16: Jay Hazlewood | D16: (480) 717-9339 | E16: 110 | F16: 2400000 | G16: 20000000 | H16: HVAC + Plumbing | I16: Sedona | J16: AZ | K16: (928) 224-1764 | M16: 1. Not Contacted | N16: Unknown | O16: =IF(B16="","",IFERROR(LOOKUP(2,1/('Call Log'!$C$2:$C$5000=B16),'Call Log'!$B$2:$B$5000),"")) | P16: =IF(B16="","",COUNTIFS('Call Log'!$C$2:$C$5000,B16,'Call Log'!$A$2:$A$5000,">="&(TODAY()-WEEKDAY(TODAY(),2)+1))) -> 0 | Q16: =IF(B16="","",COUNTIF('Call Log'!$C$2:$C$5000,B16)) -> 0 | R16: =IF(B16="","",IFERROR(IF(MAXIFS('Call Log'!$A$2:$A$5000,'Call Log'!$C$2:$C$5000,B16)=0,"",MAXIFS('Call Log'!$A$2:$A$5000,'Call Log'!$C$2:$C$5000,B16)),"")) | AA16: Contact title 'Owner' - verify decision maker | Owner found via Apollo | EBITDA = 12% revenue proxy
A17: C016 | B17: Benefit Air Conditioning | C17: Michael Sean Elia | D17: (602) 293-6293 | E17: 8 | F17: 2393000 | G17: 19943000 | H17: HVAC | I17: Phoenix | J17: AZ | K17: (602) 840-9229 | L17: mike@benefitair.com | M17: 1. Not Contacted | N17: Unknown | O17: =IF(B17="","",IFERROR(LOOKUP(2,1/('Call Log'!$C$2:$C$5000=B17),'Call Log'!$B$2:$B$5000),"")) | P17: =IF(B17="","",COUNTIFS('Call Log'!$C$2:$C$5000,B17,'Call Log'!$A$2:$A$5000,">="&(TODAY()-WEEKDAY(TODAY(),2)+1))) -> 0 | Q17: =IF(B17="","",COUNTIF('Call Log'!$C$2:$C$5000,B17)) -> 0 | R17: =IF(B17="","",IFERROR(IF(MAXIFS('Call Log'!$A$2:$A$5000,'Call Log'!$C$2:$C$5000,B17)=0,"",MAXIFS('Call Log'!$A$2:$A$5000,'Call Log'!$C$2:$C$5000,B17)),"")) | Z17: roc-apify | AA17: ROC 173187 | EBITDA = 12% revenue proxy
A18: C017 | B18: Intermountain Plumbing & Mechanical | C18: David Allen Pulley | D18: (928) 220-1361 | E18: 9 | F18: 2296000 | G18: 19132000 | H18: Plumbing | I18: Flagstaff | J18: AZ | K18: (928) 526-7006 | L18: dave@intermountainaz.com | M18: 1. Not Contacted | N18: Unknown | O18: =IF(B18="","",IFERROR(LOOKUP(2,1/('Call Log'!$C$2:$C$5000=B18),'Call Log'!$B$2:$B$5000),"")) | P18: =IF(B18="","",COUNTIFS('Call Log'!$C$2:$C$5000,B18,'Call Log'!$A$2:$A$5000,">="&(TODAY()-WEEKDAY(TODAY(),2)+1))) -> 0 | Q18: =IF(B18="","",COUNTIF('Call Log'!$C$2:$C$5000,B18)) -> 0 | R18: =IF(B18="","",IFERROR(IF(MAXIFS('Call Log'!$A$2:$A$5000,'Call Log'!$C$2:$C$5000,B18)=0,"",MAXIFS('Call Log'!$A$2:$A$5000,'Call Log'!$C$2:$C$5000,B18)),"")) | Z18: roc-posting-list | AA18: Contact title 'General Manager' - verify decision maker | ROC 91860 R-37R | EBITDA = 12% revenue proxy
A19: C018 | B19: Comfort Pro Heating & Cooling, Inc. | C19: Robert Uwe Kunzmann | D19: (928) 927-9000 | E19: 6 | F19: 2169000 | G19: 18079000 | H19: HVAC | I19: Prescott | J19: AZ | K19: (928) 899-4250 | L19: robkunzmann@prorvandair.com | M19: 1. Not Contacted | N19: Unknown | O19: =IF(B19="","",IFERROR(LOOKUP(2,1/('Call Log'!$C$2:$C$5000=B19),'Call Log'!$B$2:$B$5000),"")) | P19: =IF(B19="","",COUNTIFS('Call Log'!$C$2:$C$5000,B19,'Call Log'!$A$2:$A$5000,">="&(TODAY()-WEEKDAY(TODAY(),2)+1))) -> 0 | Q19: =IF(B19="","",COUNTIF('Call Log'!$C$2:$C$5000,B19)) -> 0 | R19: =IF(B19="","",IFERROR(IF(MAXIFS('Call Log'!$A$2:$A$5000,'Call Log'!$C$2:$C$5000,B19)=0,"",MAXIFS('Call Log'!$A$2:$A$5000,'Call Log'!$C$2:$C$5000,B19)),"")) | Z19: roc-posting-list | AA19: ROC 241514 R-39R | EBITDA = 12% revenue proxy
A20: C019 | B20: Efficiency Heating & Cooling LLC | C20: Drew Nicholas | D20: (602) 919-4054 | E20: 20 | F20: 1830000 | G20: 15247000 | H20: HVAC | I20: Gilbert | J20: AZ | K20: (480) 331-8904 | L20: drew@effmech.com | M20: 1. Not Contacted | N20: Unknown | O20: =IF(B20="","",IFERROR(LOOKUP(2,1/('Call Log'!$C$2:$C$5000=B20),'Call Log'!$B$2:$B$5000),"")) | P20: =IF(B20="","",COUNTIFS('Call Log'!$C$2:$C$5000,B20,'Call Log'!$A$2:$A$5000,">="&(TODAY()-WEEKDAY(TODAY(),2)+1))) -> 0 | Q20: =IF(B20="","",COUNTIF('Call Log'!$C$2:$C$5000,B20)) -> 0 | R20: =IF(B20="","",IFERROR(IF(MAXIFS('Call Log'!$A$2:$A$5000,'Call Log'!$C$2:$C$5000,B20)=0,"",MAXIFS('Call Log'!$A$2:$A$5000,'Call Log'!$C$2:$C$5000,B20)),"")) | Z20: roc-posting-list | AA20: Contact title 'Project Manager' - verify decision maker | ROC 319039 CR-39 | EBITDA = 12% revenue proxy
A21: C020 | B21: Cool Blew Inc. | C21: Robert Leon Proctor | D21: (602) 292-3707 | E21: 11 | F21: 1740000 | G21: 14500000 | H21: HVAC | I21: Peoria | J21: AZ | K21: (623) 872-2900 | M21: 1. Not Contacted | N21: Unknown | O21: =IF(B21="","",IFERROR(LOOKUP(2,1/('Call Log'!$C$2:$C$5000=B21),'Call Log'!$B$2:$B$5000),"")) | P21: =IF(B21="","",COUNTIFS('Call Log'!$C$2:$C$5000,B21,'Call Log'!$A$2:$A$5000,">="&(TODAY()-WEEKDAY(TODAY(),2)+1))) -> 0 | Q21: =IF(B21="","",COUNTIF('Call Log'!$C$2:$C$5000,B21)) -> 0 | R21: =IF(B21="","",IFERROR(IF(MAXIFS('Call Log'!$A$2:$A$5000,'Call Log'!$C$2:$C$5000,B21)=0,"",MAXIFS('Call Log'!$A$2:$A$5000,'Call Log'!$C$2:$C$5000,B21)),"")) | Z21: roc-posting-list | AA21: Other locations: Surprise | ROC 176357 CR-39 | EBITDA = 12% revenue proxy
A22: C021 | B22: EZ Flow Plumbing, LLC | C22: Scott William Reisack | D22: (480) 340-0752 | E22: 6 | F22: 1334000 | G22: 11120000 | H22: Plumbing | I22: Chandler | J22: AZ | K22: (602) 613-4525 | L22: scott@ezflowplumbingaz.com | M22: 1. Not Contacted | N22: Unknown | O22: =IF(B22="","",IFERROR(LOOKUP(2,1/('Call Log'!$C$2:$C$5000=B22),'Call Log'!$B$2:$B$5000),"")) | P22: =IF(B22="","",COUNTIFS('Call Log'!$C$2:$C$5000,B22,'Call Log'!$A$2:$A$5000,">="&(TODAY()-WEEKDAY(TODAY(),2)+1))) -> 0 | Q22: =IF(B22="","",COUNTIF('Call Log'!$C$2:$C$5000,B22)) -> 0 | R22: =IF(B22="","",IFERROR(IF(MAXIFS('Call Log'!$A$2:$A$5000,'Call Log'!$C$2:$C$5000,B22)=0,"",MAXIFS('Call Log'!$A$2:$A$5000,'Call Log'!$C$2:$C$5000,B22)),"")) | Z22: roc-posting-list | AA22: Other locations: Tempe | ROC 242432 CR-37 | EBITDA = 12% revenue proxy
A23: C022 | B23: SMW Refrigeration and Heating, LLC | C23: Scott Michael Wetter | D23: (480) 462-6650 | E23: 12 | F23: 1178000 | G23: 9817000 | H23: HVAC | I23: Tempe | J23: AZ | K23: (855) 875-2665 | L23: scott@smwrefrigeration.com | M23: 1. Not Contacted | N23: Unknown | O23: =IF(B23="","",IFERROR(LOOKUP(2,1/('Call Log'!$C$2:$C$5000=B23),'Call Log'!$B$2:$B$5000),"")) | P23: =IF(B23="","",COUNTIFS('Call Log'!$C$2:$C$5000,B23,'Call Log'!$A$2:$A$5000,">="&(TODAY()-WEEKDAY(TODAY(),2)+1))) -> 0 | Q23: =IF(B23="","",COUNTIF('Call Log'!$C$2:$C$5000,B23)) -> 0 | R23: =IF(B23="","",IFERROR(IF(MAXIFS('Call Log'!$A$2:$A$5000,'Call Log'!$C$2:$C$5000,B23)=0,"",MAXIFS('Call Log'!$A$2:$A$5000,'Call Log'!$C$2:$C$5000,B23)),"")) | Z23: roc-posting-list | AA23: ROC 172364 R-39R | EBITDA = 12% revenue proxy
A24: C023 | B24: Curtis Plumbing | C24: Jonathan Curtis | D24: (813) 951-3459 | E24: 8 | F24: 1167000 | G24: 9721000 | H24: Plumbing | I24: Tucson | J24: AZ | K24: (520) 323-7697 | M24: 1. Not Contacted | N24: Unknown | O24: =IF(B24="","",IFERROR(LOOKUP(2,1/('Call Log'!$C$2:$C$5000=B24),'Call Log'!$B$2:$B$5000),"")) | P24: =IF(B24="","",COUNTIFS('Call Log'!$C$2:$C$5000,B24,'Call Log'!$A$2:$A$5000,">="&(TODAY()-WEEKDAY(TODAY(),2)+1))) -> 0 | Q24: =IF(B24="","",COUNTIF('Call Log'!$C$2:$C$5000,B24)) -> 0 | R24: =IF(B24="","",IFERROR(IF(MAXIFS('Call Log'!$A$2:$A$5000,'Call Log'!$C$2:$C$5000,B24)=0,"",MAXIFS('Call Log'!$A$2:$A$5000,'Call Log'!$C$2:$C$5000,B24)),"")) | AA24: Owner found via Apollo | ROC 61230 R-37R | EBITDA = 12% revenue proxy
A25: C024 | B25: Reddi Services | C25: Danny Ray Gravatt | D25: (913) 731-0237 | E25: 49 | F25: 1154000 | G25: 9615000 | H25: HVAC + Plumbing | I25: Peoria | J25: AZ | K25: (602) 789-3910 | L25: danny@reddiservices.com | M25: 1. Not Contacted | N25: Unknown | O25: =IF(B25="","",IFERROR(LOOKUP(2,1/('Call Log'!$C$2:$C$5000=B25),'Call Log'!$B$2:$B$5000),"")) | P25: =IF(B25="","",COUNTIFS('Call Log'!$C$2:$C$5000,B25,'Call Log'!$A$2:$A$5000,">="&(TODAY()-WEEKDAY(TODAY(),2)+1))) -> 0 | Q25: =IF(B25="","",COUNTIF('Call Log'!$C$2:$C$5000,B25)) -> 0 | R25: =IF(B25="","",IFERROR(IF(MAXIFS('Call Log'!$A$2:$A$5000,'Call Log'!$C$2:$C$5000,B25)=0,"",MAXIFS('Call Log'!$A$2:$A$5000,'Call Log'!$C$2:$C$5000,B25)),"")) | Z25: roc-posting-list | AA25: Contact title 'Division Manager Plumbing, Excavation and Liquid Waste Hauling' - verify decision maker | ROC 202706 CR-37 | EBITDA = 12% revenue proxy
A26: C025 | B26: Temperature Control, Inc. A/C-Heating & Plumbing - Tucson, AZ | C26: Vance Macleod | D26: (520) 314-2110 | E26: 12 | F26: 1105000 | G26: 9212000 | H26: HVAC | I26: Tucson | J26: AZ | K26: (520) 775-3566 | M26: 1. Not Contacted | N26: Unknown | O26: =IF(B26="","",IFERROR(LOOKUP(2,1/('Call Log'!$C$2:$C$5000=B26),'Call Log'!$B$2:$B$5000),"")) | P26: =IF(B26="","",COUNTIFS('Call Log'!$C$2:$C$5000,B26,'Call Log'!$A$2:$A$5000,">="&(TODAY()-WEEKDAY(TODAY(),2)+1))) -> 0 | Q26: =IF(B26="","",COUNTIF('Call Log'!$C$2:$C$5000,B26)) -> 0 | R26: =IF(B26="","",IFERROR(IF(MAXIFS('Call Log'!$A$2:$A$5000,'Call Log'!$C$2:$C$5000,B26)=0,"",MAXIFS('Call Log'!$A$2:$A$5000,'Call Log'!$C$2:$C$5000,B26)),"")) | AA26: Owner found via Apollo | EBITDA = 12% revenue proxy
A27: C026 | B27: Temperature Control, Inc. A/C-Heating & Plumbing - Oro Valley, AZ | C27: Vance Macleod | D27: (520) 314-2110 | E27: 12 | F27: 1105000 | G27: 9212000 | H27: HVAC + Plumbing | I27: Tucson | J27: AZ | K27: (520) 201-5414 | M27: 1. Not Contacted | N27: Unknown | O27: =IF(B27="","",IFERROR(LOOKUP(2,1/('Call Log'!$C$2:$C$5000=B27),'Call Log'!$B$2:$B$5000),"")) | P27: =IF(B27="","",COUNTIFS('Call Log'!$C$2:$C$5000,B27,'Call Log'!$A$2:$A$5000,">="&(TODAY()-WEEKDAY(TODAY(),2)+1))) -> 0 | Q27: =IF(B27="","",COUNTIF('Call Log'!$C$2:$C$5000,B27)) -> 0 | R27: =IF(B27="","",IFERROR(IF(MAXIFS('Call Log'!$A$2:$A$5000,'Call Log'!$C$2:$C$5000,B27)=0,"",MAXIFS('Call Log'!$A$2:$A$5000,'Call Log'!$C$2:$C$5000,B27)),"")) | AA27: Owner found via Apollo | EBITDA = 12% revenue proxy
A28: C027 | B28: Anthony James Air Conditioning & Heating | C28: Anthony James Garcia | D28: (623) 670-1974 | E28: 1 | F28: 1101000 | G28: 9176000 | H28: HVAC | I28: Peoria | J28: AZ | K28: (623) 556-3852 | M28: 1. Not Contacted | N28: Unknown | O28: =IF(B28="","",IFERROR(LOOKUP(2,1/('Call Log'!$C$2:$C$5000=B28),'Call Log'!$B$2:$B$5000),"")) | P28: =IF(B28="","",COUNTIFS('Call Log'!$C$2:$C$5000,B28,'Call Log'!$A$2:$A$5000,">="&(TODAY()-WEEKDAY(TODAY(),2)+1))) -> 0 | Q28: =IF(B28="","",COUNTIF('Call Log'!$C$2:$C$5000,B28)) -> 0 | R28: =IF(B28="","",IFERROR(IF(MAXIFS('Call Log'!$A$2:$A$5000,'Call Log'!$C$2:$C$5000,B28)=0,"",MAXIFS('Call Log'!$A$2:$A$5000,'Call Log'!$C$2:$C$5000,B28)),"")) | Z28: roc-posting-list | AA28: Contact title 'Co Owner' - verify decision maker | ROC 240848 R-39 | EBITDA = 12% revenue proxy
A29: C028 | B29: DeGeorge Plumbing and HVAC | C29: Timothy L Chatburn | D29: +1 312-975-8109 | E29: 2 | F29: 1050000 | G29: 8753000 | H29: Plumbing | I29: Phoenix | J29: AZ | K29: (602) 830-3977 | M29: 1. Not Contacted | N29: Unknown | O29: =IF(B29="","",IFERROR(LOOKUP(2,1/('Call Log'!$C$2:$C$5000=B29),'Call Log'!$B$2:$B$5000),"")) | P29: =IF(B29="","",COUNTIFS('Call Log'!$C$2:$C$5000,B29,'Call Log'!$A$2:$A$5000,">="&(TODAY()-WEEKDAY(TODAY(),2)+1))) -> 0 | Q29: =IF(B29="","",COUNTIF('Call Log'!$C$2:$C$5000,B29)) -> 0 | R29: =IF(B29="","",IFERROR(IF(MAXIFS('Call Log'!$A$2:$A$5000,'Call Log'!$C$2:$C$5000,B29)=0,"",MAXIFS('Call Log'!$A$2:$A$5000,'Call Log'!$C$2:$C$5000,B29)),"")) | Z29: roc-posting-list | AA29: Cell pulled from Apollo contacts | ROC 342832 CR-77 | EBITDA = 12% revenue proxy
A30: C029 | B30: Hobaica Services | C30: Louis Gerard Hobaica | D30: (602) 721-1389 | E30: 32 | F30: 1032000 | G30: 8600000 | H30: HVAC | I30: Phoenix | J30: AZ | K30: (602) 675-8338 | L30: lhobaica@hobaica.com | M30: 1. Not Contacted | N30: Unknown | O30: =IF(B30="","",IFERROR(LOOKUP(2,1/('Call Log'!$C$2:$C$5000=B30),'Call Log'!$B$2:$B$5000),"")) | P30: =IF(B30="","",COUNTIFS('Call Log'!$C$2:$C$5000,B30,'Call Log'!$A$2:$A$5000,">="&(TODAY()-WEEKDAY(TODAY(),2)+1))) -> 0 | Q30: =IF(B30="","",COUNTIF('Call Log'!$C$2:$C$5000,B30)) -> 0 | R30: =IF(B30="","",IFERROR(IF(MAXIFS('Call Log'!$A$2:$A$5000,'Call Log'!$C$2:$C$5000,B30)=0,"",MAXIFS('Call Log'!$A$2:$A$5000,'Call Log'!$C$2:$C$5000,B30)),"")) | Z30: roc-posting-list | AA30: Co-owners: Brian Lee Sorensen | ROC 334988 CR-77 | EBITDA = 12% revenue proxy
A31: C030 | B31: Advantage Home Performance Inc. | C31: Michael William Uniacke | D31: (520) 717-2879 | E31: 4 | F31: 990000 | G31: 8254000 | H31: HVAC | I31: Prescott | J31: AZ | K31: (928) 445-3828 | M31: 1. Not Contacted | N31: Unknown | O31: =IF(B31="","",IFERROR(LOOKUP(2,1/('Call Log'!$C$2:$C$5000=B31),'Call Log'!$B$2:$B$5000),"")) | P31: =IF(B31="","",COUNTIFS('Call Log'!$C$2:$C$5000,B31,'Call Log'!$A$2:$A$5000,">="&(TODAY()-WEEKDAY(TODAY(),2)+1))) -> 0 | Q31: =IF(B31="","",COUNTIF('Call Log'!$C$2:$C$5000,B31)) -> 0 | R31: =IF(B31="","",IFERROR(IF(MAXIFS('Call Log'!$A$2:$A$5000,'Call Log'!$C$2:$C$5000,B31)=0,"",MAXIFS('Call Log'!$A$2:$A$5000,'Call Log'!$C$2:$C$5000,B31)),"")) | Z31: roc-posting-list | AA31: Other locations: Glendale | ROC 274862 R-39R | EBITDA = 12% revenue proxy
A32: C031 | B32: Semper Fi Heating and Cooling | C32: Jesse Keenan | D32: (504) 682-8800 | E32: 96 | F32: 972000 | G32: 8100000 | H32: HVAC | I32: Mesa | J32: AZ | K32: (480) 741-1440 | L32: jesse@semperfiheatingcooling.com | M32: 1. Not Contacted | N32: Unknown | O32: =IF(B32="","",IFERROR(LOOKUP(2,1/('Call Log'!$C$2:$C$5000=B32),'Call Log'!$B$2:$B$5000),"")) | P32: =IF(B32="","",COUNTIFS('Call Log'!$C$2:$C$5000,B32,'Call Log'!$A$2:$A$5000,">="&(TODAY()-WEEKDAY(TODAY(),2)+1))) -> 0 | Q32: =IF(B32="","",COUNTIF('Call Log'!$C$2:$C$5000,B32)) -> 0 | R32: =IF(B32="","",IFERROR(IF(MAXIFS('Call Log'!$A$2:$A$5000,'Call Log'!$C$2:$C$5000,B32)=0,"",MAXIFS('Call Log'!$A$2:$A$5000,'Call Log'!$C$2:$C$5000,B32)),"")) | Z32: roc-posting-list | AA32: Co-owners: Steve Best | Other locations: Peoria | ROC 309388 R-39R | EBITDA = 12% revenue proxy
A33: C032 | B33: Done Rite Services - HVAC, Plumbing, & Electrical | C33: Christopher Deraffele | D33: (480) 246-7298 | E33: 42 | F33: 852000 | G33: 7100000 | H33: HVAC | I33: Tucson | J33: AZ | K33: (520) 369-3966 | M33: 1. Not Contacted | N33: Unknown | O33: =IF(B33="","",IFERROR(LOOKUP(2,1/('Call Log'!$C$2:$C$5000=B33),'Call Log'!$B$2:$B$5000),"")) | P33: =IF(B33="","",COUNTIFS('Call Log'!$C$2:$C$5000,B33,'Call Log'!$A$2:$A$5000,">="&(TODAY()-WEEKDAY(TODAY(),2)+1))) -> 0 | Q33: =IF(B33="","",COUNTIF('Call Log'!$C$2:$C$5000,B33)) -> 0 | R33: =IF(B33="","",IFERROR(IF(MAXIFS('Call Log'!$A$2:$A$5000,'Call Log'!$C$2:$C$5000,B33)=0,"",MAXIFS('Call Log'!$A$2:$A$5000,'Call Log'!$C$2:$C$5000,B33)),"")) | AA33: Contact title 'Owner' - verify decision maker | Owner found via Apollo | EBITDA = 12% revenue proxy
A34: C033 | B34: Hansberger Refrigeration and Electric Company | C34: Mark Allen Hansberger | D34: (928) 783-1729 | E34: 10 | F34: 787000 | G34: 6561000 | H34: HVAC | I34: Yuma | J34: AZ | K34: (928) 783-3331 | L34: markh@hreaz.com | M34: 1. Not Contacted | N34: Unknown | O34: =IF(B34="","",IFERROR(LOOKUP(2,1/('Call Log'!$C$2:$C$5000=B34),'Call Log'!$B$2:$B$5000),"")) | P34: =IF(B34="","",COUNTIFS('Call Log'!$C$2:$C$5000,B34,'Call Log'!$A$2:$A$5000,">="&(TODAY()-WEEKDAY(TODAY(),2)+1))) -> 0 | Q34: =IF(B34="","",COUNTIF('Call Log'!$C$2:$C$5000,B34)) -> 0 | R34: =IF(B34="","",IFERROR(IF(MAXIFS('Call Log'!$A$2:$A$5000,'Call Log'!$C$2:$C$5000,B34)=0,"",MAXIFS('Call Log'!$A$2:$A$5000,'Call Log'!$C$2:$C$5000,B34)),"")) | Z34: roc-posting-list | AA34: ROC 161695 CR-39 | EBITDA = 12% revenue proxy
A35: C034 | B35: North Valley Mechanical HVAC & Plumbing | C35: Kirk Buscho | D35: (602) 448-5255 | E35: 15 | F35: 703000 | G35: 5860000 | H35: HVAC | I35: Phoenix | J35: AZ | K35: (602) 975-4247 | M35: 1. Not Contacted | N35: Unknown | O35: =IF(B35="","",IFERROR(LOOKUP(2,1/('Call Log'!$C$2:$C$5000=B35),'Call Log'!$B$2:$B$5000),"")) | P35: =IF(B35="","",COUNTIFS('Call Log'!$C$2:$C$5000,B35,'Call Log'!$A$2:$A$5000,">="&(TODAY()-WEEKDAY(TODAY(),2)+1))) -> 0 | Q35: =IF(B35="","",COUNTIF('Call Log'!$C$2:$C$5000,B35)) -> 0 | R35: =IF(B35="","",IFERROR(IF(MAXIFS('Call Log'!$A$2:$A$5000,'Call Log'!$C$2:$C$5000,B35)=0,"",MAXIFS('Call Log'!$A$2:$A$5000,'Call Log'!$C$2:$C$5000,B35)),"")) | Z35: roc-posting-list | AA35: ROC 281777 CR-79 | EBITDA = 12% revenue proxy
A36: C035 | B36: Lee's Air, Plumbing, & Heating | C36: Thomas Edward Howard | D36: (559) 259-1244 | E36: 98 | F36: 684000 | G36: 5700000 | H36: HVAC | I36: Peoria | J36: AZ | K36: (602) 649-2180 | L36: thoward@servicetitan.com | M36: 1. Not Contacted | N36: Unknown | O36: =IF(B36="","",IFERROR(LOOKUP(2,1/('Call Log'!$C$2:$C$5000=B36),'Call Log'!$B$2:$B$5000),"")) | P36: =IF(B36="","",COUNTIFS('Call Log'!$C$2:$C$5000,B36,'Call Log'!$A$2:$A$5000,">="&(TODAY()-WEEKDAY(TODAY(),2)+1))) -> 0 | Q36: =IF(B36="","",COUNTIF('Call Log'!$C$2:$C$5000,B36)) -> 0 | R36: =IF(B36="","",IFERROR(IF(MAXIFS('Call Log'!$A$2:$A$5000,'Call Log'!$C$2:$C$5000,B36)=0,"",MAXIFS('Call Log'!$A$2:$A$5000,'Call Log'!$C$2:$C$5000,B36)),"")) | Z36: roc-posting-list | AA36: Contact title 'VP Customer Experience' - verify decision maker | ROC 358197 CR-37 | EBITDA = 12% revenue proxy
A37: C036 | B37: Ambient Edge Heating, Air Conditioning & Refrigeration Inc. | C37: Steven Lewis | D37: (928) 279-1017 | E37: 30 | F37: 681000 | G37: 5676000 | H37: HVAC + Plumbing | I37: Kingman | J37: AZ | K37: (928) 615-8224 | L37: slewis@ambientedge.com | M37: 1. Not Contacted | N37: Unknown | O37: =IF(B37="","",IFERROR(LOOKUP(2,1/('Call Log'!$C$2:$C$5000=B37),'Call Log'!$B$2:$B$5000),"")) | P37: =IF(B37="","",COUNTIFS('Call Log'!$C$2:$C$5000,B37,'Call Log'!$A$2:$A$5000,">="&(TODAY()-WEEKDAY(TODAY(),2)+1))) -> 0 | Q37: =IF(B37="","",COUNTIF('Call Log'!$C$2:$C$5000,B37)) -> 0 | R37: =IF(B37="","",IFERROR(IF(MAXIFS('Call Log'!$A$2:$A$5000,'Call Log'!$C$2:$C$5000,B37)=0,"",MAXIFS('Call Log'!$A$2:$A$5000,'Call Log'!$C$2:$C$5000,B37)),"")) | AA37: Owner found via Apollo | EBITDA = 12% revenue proxy
A38: C037 | B38: Ambient Edge Cooling, Heating & Plumbing | C38: Steven Ray Lewis | D38: (928) 279-1017 | E38: 30 | F38: 681000 | G38: 5676000 | H38: HVAC | I38: Lake Havasu City | J38: AZ | K38: (928) 569-9545 | L38: slewis@ambientedge.com | M38: 1. Not Contacted | N38: Unknown | O38: =IF(B38="","",IFERROR(LOOKUP(2,1/('Call Log'!$C$2:$C$5000=B38),'Call Log'!$B$2:$B$5000),"")) | P38: =IF(B38="","",COUNTIFS('Call Log'!$C$2:$C$5000,B38,'Call Log'!$A$2:$A$5000,">="&(TODAY()-WEEKDAY(TODAY(),2)+1))) -> 0 | Q38: =IF(B38="","",COUNTIF('Call Log'!$C$2:$C$5000,B38)) -> 0 | R38: =IF(B38="","",IFERROR(IF(MAXIFS('Call Log'!$A$2:$A$5000,'Call Log'!$C$2:$C$5000,B38)=0,"",MAXIFS('Call Log'!$A$2:$A$5000,'Call Log'!$C$2:$C$5000,B38)),"")) | Z38: roc-posting-list | AA38: ROC 333029 CR-39 | EBITDA = 12% revenue proxy
A39: C038 | B39: Intelligent Design Air Conditioning, Plumbing, Solar, & Electric | C39: Andrew Dobbins | D39: (520) 780-7233 | E39: 16 | F39: 657000 | G39: 5476000 | H39: HVAC | I39: Tucson | J39: AZ | K39: (520) 333-2665 | L39: andrew@idesignac.com | M39: 1. Not Contacted | N39: Unknown | O39: =IF(B39="","",IFERROR(LOOKUP(2,1/('Call Log'!$C$2:$C$5000=B39),'Call Log'!$B$2:$B$5000),"")) | P39: =IF(B39="","",COUNTIFS('Call Log'!$C$2:$C$5000,B39,'Call Log'!$A$2:$A$5000,">="&(TODAY()-WEEKDAY(TODAY(),2)+1))) -> 0 | Q39: =IF(B39="","",COUNTIF('Call Log'!$C$2:$C$5000,B39)) -> 0 | R39: =IF(B39="","",IFERROR(IF(MAXIFS('Call Log'!$A$2:$A$5000,'Call Log'!$C$2:$C$5000,B39)=0,"",MAXIFS('Call Log'!$A$2:$A$5000,'Call Log'!$C$2:$C$5000,B39)),"")) | AA39: Owner found via Apollo | EBITDA = 12% revenue proxy
A40: C039 | B40: Collins Commercial Services | C40: Chad Christian Collins | D40: (480) 926-1975 | E40: 31 | F40: 615000 | G40: 5125000 | H40: Plumbing | I40: Scottsdale | J40: AZ | K40: (844) 493-2974 | L40: chad@collins-cs.com | M40: 1. Not Contacted | N40: Unknown | O40: =IF(B40="","",IFERROR(LOOKUP(2,1/('Call Log'!$C$2:$C$5000=B40),'Call Log'!$B$2:$B$5000),"")) | P40: =IF(B40="","",COUNTIFS('Call Log'!$C$2:$C$5000,B40,'Call Log'!$A$2:$A$5000,">="&(TODAY()-WEEKDAY(TODAY(),2)+1))) -> 0 | Q40: =IF(B40="","",COUNTIF('Call Log'!$C$2:$C$5000,B40)) -> 0 | R40: =IF(B40="","",IFERROR(IF(MAXIFS('Call Log'!$A$2:$A$5000,'Call Log'!$C$2:$C$5000,B40)=0,"",MAXIFS('Call Log'!$A$2:$A$5000,'Call Log'!$C$2:$C$5000,B40)),"")) | Z40: roc-posting-list | AA40: ROC 206292 CR-37 | EBITDA = 12% revenue proxy
...

Sheet Call Log
A1: Date | B1: Caller | C1: Company Name | D1: Reached | E1: Outcome | F1: Interest After Call | G1: Mins | H1: Call Summary | I1: Next Step | J1: Follow-Up Date

Sheet SMS Nurture
A1: Company (pick from list) | B1: Owner | C1: Owner Cell | D1: Date Added | E1: Said No To | F1: Last Text Sent | G1: Next Text Due | H1: Status | I1: Notes | K1: MONTHLY TEXT SCRIPTS - rotate so it never reads copy-paste. Send MANUALLY, one at a time, from your own phone.
B2: {=IF($A2="","",IFERROR(INDEX(Companies!$C$2:$C$1000,MATCH($A2,Companies!$B$2:$B$1000,0)),""))} | C2: {=IF($A2="","",IFERROR(INDEX(Companies!$D$2:$D$1000,MATCH($A2,Companies!$B$2:$B$1000,0)),""))} | G2: =IF($A2="","",IF($F2<>"",$F2+30,IF($D2<>"",$D2+30,""))) | K2: Month 1: Hi [Owner], [Your name] here - we spoke a while back about [Company]. No pitch, just keeping the door open: if you ever want to know what a shop like yours is going for right now, happy to share. Either way, keep crushing it.
B3: {=IF($A3="","",IFERROR(INDEX(Companies!$C$2:$C$1000,MATCH($A3,Companies!$B$2:$B$1000,0)),""))} | C3: {=IF($A3="","",IFERROR(INDEX(Companies!$D$2:$D$1000,MATCH($A3,Companies!$B$2:$B$1000,0)),""))} | G3: =IF($A3="","",IF($F3<>"",$F3+30,IF($D3<>"",$D3+30,""))) | K3: Month 2: Hi [Owner], [Your name] again. We just closed on another [trade] company in the area. If you're ever curious how [Company] stacks up value-wise, it's a 10-minute call. Zero pressure.
B4: {=IF($A4="","",IFERROR(INDEX(Companies!$C$2:$C$1000,MATCH($A4,Companies!$B$2:$B$1000,0)),""))} | C4: {=IF($A4="","",IFERROR(INDEX(Companies!$D$2:$D$1000,MATCH($A4,Companies!$B$2:$B$1000,0)),""))} | G4: =IF($A4="","",IF($F4<>"",$F4+30,IF($D4<>"",$D4+30,""))) | K4: Month 3: Hi [Owner] - most owners we sit down with wish they'd started the conversation two years before they wanted out. Even if selling is 5 years away for you, worth a coffee sometime?
B5: {=IF($A5="","",IFERROR(INDEX(Companies!$C$2:$C$1000,MATCH($A5,Companies!$B$2:$B$1000,0)),""))} | C5: {=IF($A5="","",IFERROR(INDEX(Companies!$D$2:$D$1000,MATCH($A5,Companies!$B$2:$B$1000,0)),""))} | G5: =IF($A5="","",IF($F5<>"",$F5+30,IF($D5<>"",$D5+30,""))) | K5: Month 4: Hi [Owner], still serious about buying [Company] whenever the timing is right for you. You know where to find me. - [Your name]
B6: {=IF($A6="","",IFERROR(INDEX(Companies!$C$2:$C$1000,MATCH($A6,Companies!$B$2:$B$1000,0)),""))} | C6: {=IF($A6="","",IFERROR(INDEX(Companies!$D$2:$D$1000,MATCH($A6,Companies!$B$2:$B$1000,0)),""))} | G6: =IF($A6="","",IF($F6<>"",$F6+30,IF($D6<>"",$D6+30,"")))
B7: {=IF($A7="","",IFERROR(INDEX(Companies!$C$2:$C$1000,MATCH($A7,Companies!$B$2:$B$1000,0)),""))} | C7: {=IF($A7="","",IFERROR(INDEX(Companies!$D$2:$D$1000,MATCH($A7,Companies!$B$2:$B$1000,0)),""))} | G7: =IF($A7="","",IF($F7<>"",$F7+30,IF($D7<>"",$D7+30,""))) | K7: THE RULES: If anyone replies STOP, 'don't text me', or anything like it - set Status to OPTED OUT immediately and never text again.
B8: {=IF($A8="","",IFERROR(INDEX(Companies!$C$2:$C$1000,MATCH($A8,Companies!$B$2:$B$1000,0)),""))} | C8: {=IF($A8="","",IFERROR(INDEX(Companies!$D$2:$D$1000,MATCH($A8,Companies!$B$2:$B$1000,0)),""))} | G8: =IF($A8="","",IF($F8<>"",$F8+30,IF($D8<>"",$D8+30,""))) | K8: Do NOT load these numbers into a mass-texting app. Nobody on this list opted in; blasting them is TCPA exposure at $500-$1,500 per text. Manual, personal, one at a time.
B9: {=IF($A9="","",IFERROR(INDEX(Companies!$C$2:$C$1000,MATCH($A9,Companies!$B$2:$B$1000,0)),""))} | C9: {=IF($A9="","",IFERROR(INDEX(Companies!$D$2:$D$1000,MATCH($A9,Companies!$B$2:$B$1000,0)),""))} | G9: =IF($A9="","",IF($F9<>"",$F9+30,IF($D9<>"",$D9+30,"")))
B10: {=IF($A10="","",IFERROR(INDEX(Companies!$C$2:$C$1000,MATCH($A10,Companies!$B$2:$B$1000,0)),""))} | C10: {=IF($A10="","",IFERROR(INDEX(Companies!$D$2:$D$1000,MATCH($A10,Companies!$B$2:$B$1000,0)),""))} | G10: =IF($A10="","",IF($F10<>"",$F10+30,IF($D10<>"",$D10+30,"")))
B11: {=IF($A11="","",IFERROR(INDEX(Companies!$C$2:$C$1000,MATCH($A11,Companies!$B$2:$B$1000,0)),""))} | C11: {=IF($A11="","",IFERROR(INDEX(Companies!$D$2:$D$1000,MATCH($A11,Companies!$B$2:$B$1000,0)),""))} | G11: =IF($A11="","",IF($F11<>"",$F11+30,IF($D11<>"",$D11+30,"")))
B12: {=IF($A12="","",IFERROR(INDEX(Companies!$C$2:$C$1000,MATCH($A12,Companies!$B$2:$B$1000,0)),""))} | C12: {=IF($A12="","",IFERROR(INDEX(Companies!$D$2:$D$1000,MATCH($A12,Companies!$B$2:$B$1000,0)),""))} | G12: =IF($A12="","",IF($F12<>"",$F12+30,IF($D12<>"",$D12+30,"")))
B13: {=IF($A13="","",IFERROR(INDEX(Companies!$C$2:$C$1000,MATCH($A13,Companies!$B$2:$B$1000,0)),""))} | C13: {=IF($A13="","",IFERROR(INDEX(Companies!$D$2:$D$1000,MATCH($A13,Companies!$B$2:$B$1000,0)),""))} | G13: =IF($A13="","",IF($F13<>"",$F13+30,IF($D13<>"",$D13+30,"")))
B14: {=IF($A14="","",IFERROR(INDEX(Companies!$C$2:$C$1000,MATCH($A14,Companies!$B$2:$B$1000,0)),""))} | C14: {=IF($A14="","",IFERROR(INDEX(Companies!$D$2:$D$1000,MATCH($A14,Companies!$B$2:$B$1000,0)),""))} | G14: =IF($A14="","",IF($F14<>"",$F14+30,IF($D14<>"",$D14+30,"")))
B15: {=IF($A15="","",IFERROR(INDEX(Companies!$C$2:$C$1000,MATCH($A15,Companies!$B$2:$B$1000,0)),""))} | C15: {=IF($A15="","",IFERROR(INDEX(Companies!$D$2:$D$1000,MATCH($A15,Companies!$B$2:$B$1000,0)),""))} | G15: =IF($A15="","",IF($F15<>"",$F15+30,IF($D15<>"",$D15+30,"")))
B16: {=IF($A16="","",IFERROR(INDEX(Companies!$C$2:$C$1000,MATCH($A16,Companies!$B$2:$B$1000,0)),""))} | C16: {=IF($A16="","",IFERROR(INDEX(Companies!$D$2:$D$1000,MATCH($A16,Companies!$B$2:$B$1000,0)),""))} | G16: =IF($A16="","",IF($F16<>"",$F16+30,IF($D16<>"",$D16+30,"")))
B17: {=IF($A17="","",IFERROR(INDEX(Companies!$C$2:$C$1000,MATCH($A17,Companies!$B$2:$B$1000,0)),""))} | C17: {=IF($A17="","",IFERROR(INDEX(Companies!$D$2:$D$1000,MATCH($A17,Companies!$B$2:$B$1000,0)),""))} | G17: =IF($A17="","",IF($F17<>"",$F17+30,IF($D17<>"",$D17+30,"")))
B18: {=IF($A18="","",IFERROR(INDEX(Companies!$C$2:$C$1000,MATCH($A18,Companies!$B$2:$B$1000,0)),""))} | C18: {=IF($A18="","",IFERROR(INDEX(Companies!$D$2:$D$1000,MATCH($A18,Companies!$B$2:$B$1000,0)),""))} | G18: =IF($A18="","",IF($F18<>"",$F18+30,IF($D18<>"",$D18+30,"")))
B19: {=IF($A19="","",IFERROR(INDEX(Companies!$C$2:$C$1000,MATCH($A19,Companies!$B$2:$B$1000,0)),""))} | C19: {=IF($A19="","",IFERROR(INDEX(Companies!$D$2:$D$1000,MATCH($A19,Companies!$B$2:$B$1000,0)),""))} | G19: =IF($A19="","",IF($F19<>"",$F19+30,IF($D19<>"",$D19+30,"")))
B20: {=IF($A20="","",IFERROR(INDEX(Companies!$C$2:$C$1000,MATCH($A20,Companies!$B$2:$B$1000,0)),""))} | C20: {=IF($A20="","",IFERROR(INDEX(Companies!$D$2:$D$1000,MATCH($A20,Companies!$B$2:$B$1000,0)),""))} | G20: =IF($A20="","",IF($F20<>"",$F20+30,IF($D20<>"",$D20+30,"")))
... B500: {=IF($A500="","",IFERROR(INDEX(Companies!$C$2:$C$1000,MATCH($A500,Companies!$B$2:$B$1000,0)),""))} | C500: {=IF($A500="","",IFERROR(INDEX(Companies!$D$2:$D$1000,MATCH($A500,Companies!$B$2:$B$1000,0)),""))} | G500: =IF($A500="","",IF($F500<>"",$F500+30,IF($D500<>"",$D500+30,"")))

Sheet Read Me
B2: HOW THIS SYSTEM WORKS - THE CALL -> ROUTE FLOW
B4: EVERY CALL ENDS IN ONE OF THREE ROUTES:
B5: GOOD CALL (meeting agreed): set Stage to '3. Meeting Set' on Companies, fill in Meeting Date + Meeting Time & Place. Outcome in Call Log = 'Meeting Set' (turns green).
B6: NO ANSWER / NOT YET: leave Stage at '2. In Call Rotation', set who dials next in 'Next Caller', log the attempt. A different rep takes the next dial.
B7: HARD NO: Outcome = 'Not Interested - move to SMS List'. Set Stage to 'X. SMS Nurture (Said No)', then go to the SMS Nurture tab and pick the company from the dropdown in column A - owner name and cell fill in automatically. Text them monthly from there. DO NOT keep dialing a hard no.
B9: THE ROTATION (5 callers, fresh voice each attempt):
B10: Before dialing, check 'Last Caller' and 'Calls This Wk' on Companies - both fill in automatically from the Call Log. If Last Caller was you, hand it to the rep in 'Next Caller'.
B11: Companies in rotation that nobody called this week turn ORANGE. The dashboard counts them - keep that number at zero.
B12: A word of caution from experience: rotating voices works for REACHING people who don't pick up. Re-dialing an owner who already said no - from 5 different people in one week - burns your name in a market where owners all know each other. Hard no = SMS list, not more dials.
B14: SMS NURTURE TAB:
B15: 'Next Text Due' auto-calculates 30 days after the last text (or the date added). Rows due turn YELLOW. Four rotating scripts are on the right side of that tab - personalize the brackets, send manually from your own phone, one at a time.
B16: If anyone replies STOP or asks you to quit texting: set Status to OPTED OUT (row turns red) and never contact again. Never load this list into a mass-texting platform - nobody on it opted in, and unsolicited automated texts run $500-$1,500 each in TCPA damages.
... B28: PIPELINE: 1 Not Contacted > 2 In Call Rotation > 3 Meeting Set > 4 Meeting Held > 5 NDA > 6 Financials > 7 LOI > 8 Diligence > 9 Closed. X = Said No (SMS nurture).
